Traceback (most recent call last):
  File "/usr/local/lib/python3.10/dist-packages/jupyter_cache/executors/utils.py", line 58, in single_nb_execution
    executenb(
  File "/usr/local/lib/python3.10/dist-packages/nbclient/client.py", line 1305, in execute
    return NotebookClient(nb=nb, resources=resources, km=km, **kwargs).execute()
  File "/usr/local/lib/python3.10/dist-packages/jupyter_core/utils/__init__.py", line 173, in wrapped
    return loop.run_until_complete(inner)
  File "/usr/lib/python3.10/asyncio/base_events.py", line 649, in run_until_complete
    return future.result()
  File "/usr/local/lib/python3.10/dist-packages/nbclient/client.py", line 705, in async_execute
    await self.async_execute_cell(
  File "/usr/local/lib/python3.10/dist-packages/nbclient/client.py", line 1058, in async_execute_cell
    await self._check_raise_for_error(cell, cell_index, exec_reply)
  File "/usr/local/lib/python3.10/dist-packages/nbclient/client.py", line 914, in _check_raise_for_error
    raise CellExecutionError.from_cell_and_msg(cell, exec_reply_content)
nbclient.exceptions.CellExecutionError: An error occurred while executing the following cell:
------------------
local_zip = '/content/toronto-emotional-speech-set-tess.zip'
zip_ref   = zipfile.ZipFile(local_zip, 'r')
zip_ref.extractall('/content/data')
zip_ref.close()
dataset_path = "/content/data/TESS Toronto emotional speech set data"
------------------


[0;31m---------------------------------------------------------------------------[0m
[0;31mFileNotFoundError[0m                         Traceback (most recent call last)
[0;32m<ipython-input-3-3261b375f2a2>[0m in [0;36m<cell line: 2>[0;34m()[0m
[1;32m      1[0m [0mlocal_zip[0m [0;34m=[0m [0;34m'/content/toronto-emotional-speech-set-tess.zip'[0m[0;34m[0m[0;34m[0m[0m
[0;32m----> 2[0;31m [0mzip_ref[0m   [0;34m=[0m [0mzipfile[0m[0;34m.[0m[0mZipFile[0m[0;34m([0m[0mlocal_zip[0m[0;34m,[0m [0;34m'r'[0m[0;34m)[0m[0;34m[0m[0;34m[0m[0m
[0m[1;32m      3[0m [0mzip_ref[0m[0;34m.[0m[0mextractall[0m[0;34m([0m[0;34m'/content/data'[0m[0;34m)[0m[0;34m[0m[0;34m[0m[0m
[1;32m      4[0m [0mzip_ref[0m[0;34m.[0m[0mclose[0m[0;34m([0m[0;34m)[0m[0;34m[0m[0;34m[0m[0m
[1;32m      5[0m [0mdataset_path[0m [0;34m=[0m [0;34m"/content/data/TESS Toronto emotional speech set data"[0m[0;34m[0m[0;34m[0m[0m

[0;32m/usr/lib/python3.10/zipfile.py[0m in [0;36m__init__[0;34m(self, file, mode, compression, allowZip64, compresslevel, strict_timestamps)[0m
[1;32m   1249[0m             [0;32mwhile[0m [0;32mTrue[0m[0;34m:[0m[0;34m[0m[0;34m[0m[0m
[1;32m   1250[0m                 [0;32mtry[0m[0;34m:[0m[0;34m[0m[0;34m[0m[0m
[0;32m-> 1251[0;31m                     [0mself[0m[0;34m.[0m[0mfp[0m [0;34m=[0m [0mio[0m[0;34m.[0m[0mopen[0m[0;34m([0m[0mfile[0m[0;34m,[0m [0mfilemode[0m[0;34m)[0m[0;34m[0m[0;34m[0m[0m
[0m[1;32m   1252[0m                 [0;32mexcept[0m [0mOSError[0m[0;34m:[0m[0;34m[0m[0;34m[0m[0m
[1;32m   1253[0m                     [0;32mif[0m [0mfilemode[0m [0;32min[0m [0mmodeDict[0m[0;34m:[0m[0;34m[0m[0;34m[0m[0m

[0;31mFileNotFoundError[0m: [Errno 2] No such file or directory: '/content/toronto-emotional-speech-set-tess.zip'

